Traceback (most recent call last):
  File "/workspace/.venv/lib/python3.11/site-packages/numpy/core/fromnumeric.py", line 59, in _wrapfunc
    return bound(*args, **kwds)
           ^^^^^^^^^^^^^^^^^^^^
TypeError: '>' not supported between instances of 'NoneType' and 'NoneType'

During handling of the above exception, another exception occurred:

Traceback (most recent call last):
  File "/workspace/.venv/lib/python3.11/site-packages/funsearch/container/container_main.py", line 27, in <module>
    main(sys.argv[1], sys.argv[2], sys.argv[3])
  File "/workspace/.venv/lib/python3.11/site-packages/funsearch/container/container_main.py", line 18, in main
    ret = func(input_data)
          ^^^^^^^^^^^^^^^^
  File "<ast>", line 17, in evaluate
  File "<ast>", line 33, in solve
  File "/workspace/.venv/lib/python3.11/site-packages/numpy/core/fromnumeric.py", line 1229, in argmax
    return _wrapfunc(a, 'argmax', axis=axis, out=out, **kwds)
           ^^^^^^^^^^^^^^^^^^^^^^^^^^^^^^^^^^^^^^^^^^^^^^^^^^
  File "/workspace/.venv/lib/python3.11/site-packages/numpy/core/fromnumeric.py", line 68, in _wrapfunc
    return _wrapit(obj, method, *args, **kwds)
           ^^^^^^^^^^^^^^^^^^^^^^^^^^^^^^^^^^^
  File "/workspace/.venv/lib/python3.11/site-packages/numpy/core/fromnumeric.py", line 45, in _wrapit
    result = getattr(asarray(obj), method)(*args, **kwds)
             ^^^^^^^^^^^^^^^^^^^^^^^^^^^^^^^^^^^^^^^^^^^^
TypeError: '>' not supported between instances of 'NoneType' and 'NoneType'
